# Error实例对象

js 解析或运行时，一旦发生错误，引擎就会抛出一个错误对象。js 原生提供`Error`构造函数，所有抛出的错误都是这个构造函数的实例：
```javascript
var err = new Error('出错了');
err.message // "出错了"
```

抛出`Error`实例对象以后，整个程序就中断在发生错误的地方，不再往下执行。

`Error`实例的属性有：
+ message：错误提示信息，必要属性。
+ name：错误名称（非标准属性）。
+ stack：错误的堆栈（非标准属性）。

# 原生错误类型

1. SyntaxError 对象：解析代码时发生的语法错误。
2. ReferenceError 对象：引用一个不存在的变量时发生的错误。
3. RangeError 对象：一个值超出有效范围时发生的错误。
4. TypeError 对象：变量或参数不是预期类型时发生的错误。
5. URIError 对象：URI 相关函数的参数不正确时抛出的错误。
6. EvalError 对象：`eval`函数没有被正确执行时抛出的错误。

以上这几种派生错误，连同原始的`Error`对象，都是构造函数。开发者可以手动生成错误对象的实例。构造函数都接受一个参数，代表错误提示信息（message）：
```javascript
var err1 = new Error('出错了！');
var err2 = new RangeError('出错了，变量超出有效范围！');
var err3 = new TypeError('出错了，变量类型无效！');
```

# 自定义错误类型

自定义名为`UserError`的错误类型：
```javascript
function UserError(message) {
	this.message = message || '默认信息';
	this.name = 'UserError';
}
UserError.prototype = new Error();
UserError.prototype.constructor = UserError;
```

# throw语句

使用 throw 语句可以手动中断程序执行，抛出一个错误：
```javascript
throw new Error('message');
```

# try-catch-finally语句

使用 try-catch 结构，程序不会中断，即允许对错误进行处理，按照预设流程继续执行下去：
```javascript
try {
	throw new Error('出错了!'); // 引擎发现错误，自动转到catch语句
} catch (e) { // catch将try代码块抛出的值传给参数e
	if (e instanceof EvalError) { // 判断错误类型
		console.log(e.name + ": " + e.message);
	} else if (e instanceof RangeError) {
		console.log(e.name + ": " + e.message);
	}
} finally {
	... // 无论是否出现错误，都会执行
}
```




